Workbook

Sheet Supplier_Opportunity
A3: Row Labels | B3: Sum of Opportunity_Score
A4: RedRock Supply | B4: 113236.75
A5: Titan Partners | B5: 110222.06
A6: Titan Supply | B6: 96743.936
A7: SilverLine Group | B7: 94542.15
A8: RedRock Solutions | B8: 76858.183
A9: RedRock Logistics | B9: 62917.975
A10: SilverLine Supply | B10: 55904.582
A11: Delta Logistics | B11: 53927.99
A12: SwiftHaul Components | B12: 53896.69
A13: Nova Supply | B13: 52902.96
A14: FreightBridge Partners | B14: 52862.903
A15: Skyline Group | B15: 51598.753
... A110: Grand Total | B110: 2912601.4

Sheet Raw_Data
A1: Supplier_ID | B1: Supplier_Name | C1: Region | D1: Industry | E1: Supplier_Size | F1: Annual_Spend | G1: Invoice_ID | H1: Invoice_Amount | I1: Invoice_Date | J1: Payment_Terms_Days | K1: Days_To_Approval | L1: Supplier_Borrowing_Rate | M1: SCF_Rate | N1: Early_Payment_Days | O1: Critical_Supplier_Flag | P1: Program_Eligible | Q1: Estimated_Adoption | R1: Financing_Cost_Without_SCF | S1: Financing_Cost_With_SCF | T1: Supplier_Savings | U1: Liquidity_Days_Improved | V1: Opportunity_Score | W1: Opportunity_Rank
A2: SUP115 | B2: CoreTech Supply | C2: APAC | D2: Packaging | E2: Small | F2: 1484226 | G2: INV01062 | H2: 105268 | I2: 45822 | J2: 60 | K2: 4 | L2: 0.1793 | M2: 0.0629 | N2: 6 | O2: Yes | P2: Yes | Q2: 0.9 | R2: =H2*L2*(J2/365) -> 3102.6661 | S2: =H2*M2*(N2/365) -> 108.84423 | T2: =R2-S2 -> 2993.8219 | U2: =J2-N2 -> 54 | V2: =Q2*(L2-M2)*H2 -> 11027.876 | W2: =RANK(V2,$V$2:$V$1501) -> 1
A3: SUP098 | B3: Delta Logistics | C3: Europe | D3: Ingredients | E3: Small | F3: 764840 | G3: INV00200 | H3: 109891 | I3: 45959 | J3: 60 | K3: 7 | L3: 0.1682 | M3: 0.0588 | N3: 6 | O3: No | P3: Yes | Q3: 0.9 | R3: =H3*L3*(J3/365) -> 3038.4109 | S3: =H3*M3*(N3/365) -> 106.21793 | T3: =R3-S3 -> 2932.193 | U3: =J3-N3 -> 54 | V3: =Q3*(L3-M3)*H3 -> 10819.868 | W3: =RANK(V3,$V$2:$V$1501) -> 2
A4: SUP098 | B4: Delta Logistics | C4: Europe | D4: Ingredients | E4: Small | F4: 764840 | G4: INV00061 | H4: 98760 | I4: 46052 | J4: 60 | K4: 7 | L4: 0.1682 | M4: 0.0476 | N4: 8 | O4: Yes | P4: Yes | Q4: 0.9 | R4: =H4*L4*(J4/365) -> 2730.6464 | S4: =H4*M4*(N4/365) -> 103.03509 | T4: =R4-S4 -> 2627.6113 | U4: =J4-N4 -> 52 | V4: =Q4*(L4-M4)*H4 -> 10719.41 | W4: =RANK(V4,$V$2:$V$1501) -> 3
A5: SUP137 | B5: IronRoute Systems | C5: Canada | D5: Logistics | E5: Small | F5: 876116 | G5: INV00007 | H5: 109973 | I5: 45797 | J5: 60 | K5: 3 | L5: 0.1686 | M5: 0.0476 | N5: 10 | O5: No | P5: Yes | Q5: 0.8 | R5: =H5*L5*(J5/365) -> 3047.9092 | S5: =H5*M5*(N5/365) -> 143.41684 | T5: =R5-S5 -> 2904.4924 | U5: =J5-N5 -> 50 | V5: =Q5*(L5-M5)*H5 -> 10645.386 | W5: =RANK(V5,$V$2:$V$1501) -> 4
A6: SUP035 | B6: Delta Partners | C6: Canada | D6: Logistics | E6: Small | F6: 1383695 | G6: INV00081 | H6: 109426 | I6: 45794 | J6: 60 | K6: 5 | L6: 0.1685 | M6: 0.0518 | N6: 6 | O6: No | P6: Yes | Q6: 0.8 | R6: =H6*L6*(J6/365) -> 3030.9503 | S6: =H6*M6*(N6/365) -> 93.176988 | T6: =R6-S6 -> 2937.7733 | U6: =J6-N6 -> 54 | V6: =Q6*(L6-M6)*H6 -> 10216.011 | W6: =RANK(V6,$V$2:$V$1501) -> 5
A7: SUP006 | B7: RedRock Supply | C7: Europe | D7: MRO | E7: Small | F7: 971327 | G7: INV01016 | H7: 99659 | I7: 46039 | J7: 90 | K7: 3 | L7: 0.1523 | M7: 0.0455 | N7: 10 | O7: No | P7: Yes | Q7: 0.9 | R7: =H7*L7*(J7/365) -> 3742.5367 | S7: =H7*M7*(N7/365) -> 124.23245 | T7: =R7-S7 -> 3618.3043 | U7: =J7-N7 -> 80 | V7: =Q7*(L7-M7)*H7 -> 9579.2231 | W7: =RANK(V7,$V$2:$V$1501) -> 6
A8: SUP106 | B8: GreenField Co | C8: Canada | D8: Ingredients | E8: Small | F8: 1373788 | G8: INV00025 | H8: 94978 | I8: 45878 | J8: 60 | K8: 10 | L8: 0.1766 | M8: 0.0515 | N8: 10 | O8: No | P8: Yes | Q8: 0.8 | R8: =H8*L8*(J8/365) -> 2757.2244 | S8: =H8*M8*(N8/365) -> 134.01005 | T8: =R8-S8 -> 2623.2143 | U8: =J8-N8 -> 50 | V8: =Q8*(L8-M8)*H8 -> 9505.3982 | W8: =RANK(V8,$V$2:$V$1501) -> 7
A9: SUP048 | B9: Summit Logistics | C9: US | D9: Packaging | E9: Small | F9: 467236 | G9: INV00813 | H9: 90097 | I9: 46005 | J9: 60 | K9: 4 | L9: 0.1757 | M9: 0.0457 | N9: 8 | O9: No | P9: Yes | Q9: 0.8 | R9: =H9*L9*(J9/365) -> 2602.1988 | S9: =H9*M9*(N9/365) -> 90.245105 | T9: =R9-S9 -> 2511.9537 | U9: =J9-N9 -> 52 | V9: =Q9*(L9-M9)*H9 -> 9370.088 | W9: =RANK(V9,$V$2:$V$1501) -> 8
A10: SUP013 | B10: Harbor Partners | C10: Europe | D10: Logistics | E10: Small | F10: 1439462 | G10: INV01368 | H10: 95270 | I10: 46014 | J10: 60 | K10: 2 | L10: 0.1713 | M10: 0.0512 | N10: 10 | O10: No | P10: Yes | Q10: 0.8 | R10: =H10*L10*(J10/365) -> 2682.6988 | S10: =H10*M10*(N10/365) -> 133.63901 | T10: =R10-S10 -> 2549.0598 | U10: =J10-N10 -> 50 | V10: =Q10*(L10-M10)*H10 -> 9153.5416 | W10: =RANK(V10,$V$2:$V$1501) -> 9
A11: SUP057 | B11: FreightBridge Partners | C11: Mexico | D11: Ingredients | E11: Small | F11: 946643 | G11: INV00854 | H11: 99876 | I11: 45980 | J11: 90 | K11: 10 | L11: 0.1648 | M11: 0.0505 | N11: 5 | O11: No | P11: Yes | Q11: 0.8 | R11: =H11*L11*(J11/365) -> 4058.5228 | S11: =H11*M11*(N11/365) -> 69.092301 | T11: =R11-S11 -> 3989.4305 | U11: =J11-N11 -> 85 | V11: =Q11*(L11-M11)*H11 -> 9132.6614 | W11: =RANK(V11,$V$2:$V$1501) -> 10
A12: SUP057 | B12: FreightBridge Partners | C12: Mexico | D12: Ingredients | E12: Small | F12: 946643 | G12: INV00588 | H12: 99932 | I12: 45897 | J12: 60 | K12: 2 | L12: 0.1648 | M12: 0.0645 | N12: 8 | O12: No | P12: Yes | Q12: 0.9 | R12: =H12*L12*(J12/365) -> 2707.1989 | S12: =H12*M12*(N12/365) -> 141.27373 | T12: =R12-S12 -> 2565.9252 | U12: =J12-N12 -> 52 | V12: =Q12*(L12-M12)*H12 -> 9020.8616 | W12: =RANK(V12,$V$2:$V$1501) -> 11
A13: SUP073 | B13: Skyline Group | C13: Europe | D13: Ingredients | E13: Small | F13: 261628 | G13: INV00920 | H13: 105871 | I13: 45865 | J13: 60 | K13: 4 | L13: 0.1725 | M13: 0.0452 | N13: 7 | O13: No | P13: Yes | Q13: 0.65 | R13: =H13*L13*(J13/365) -> 3002.0955 | S13: =H13*M13*(N13/365) -> 91.774204 | T13: =R13-S13 -> 2910.3213 | U13: =J13-N13 -> 53 | V13: =Q13*(L13-M13)*H13 -> 8760.2959 | W13: =RANK(V13,$V$2:$V$1501) -> 12
... A1501: SUP001 | B1501: Vertex Partners | C1501: Canada | D1501: Packaging | E1501: Medium | F1501: 1709806 | G1501: INV01500 | H1501: 29263 | I1501: 46040 | J1501: 60 | K1501: 4 | L1501: 0.1271 | M1501: 0.0582 | N1501: 10 | O1501: No | P1501: No | Q1501: 0 | R1501: =H1501*L1501*(J1501/365) -> 611.39627 | S1501: =H1501*M1501*(N1501/365) -> 46.660455 | T1501: =R1501-S1501 -> 564.73581 | U1501: =J1501-N1501 -> 50 | V1501: =Q1501*(L1501-M1501)*H1501 -> 0 | W1501: =RANK(V1501,$V$2:$V$1501) -> 1278

Sheet KPI_Dashboard
A2: Total Invoice Volume | B2: =SUM(Raw_Data!H:H) -> 91636313 | H2: Executive Summary
A3: Total Supplier Savings | B3: =SUM(Raw_Data!T:T) -> 1680346.8 | H3: 1. Supply Chain Finance could support approximately $43.9M in financed supplier invoices.
A4: Average Liquidity Days Improvement | B4: =AVERAGE(Raw_Data!U:U) -> 51.499333 | H4: 2. The program would generate an estimated $2.9M in annual revenue at a 6.63% financing spread.
A5: Average Supplier Borrowing Rate | B5: =AVERAGE(Raw_Data!L:L) -> 0.12106173 | H5: 3. Suppliers would save approximately $1.68M in financing costs, while improving liquidity by 51 days.
A6: Average SCF Rate | B6: =AVERAGE(Raw_Data!M:M) -> 0.054783133 | H6: 4.Smaller suppliers experience higher borrowing costs (≈15%), making them the strongest candidates for SCF adoption.
A7: Eligible Invoice Count | B7: =COUNTIF(Raw_Data!P:P,"Yes") -> 1277
A8: Adoption Estimate | B8: =AVERAGE(Raw_Data!Q:Q) -> 0.48206667
A9: Average Savings Per Invoice | B9: =AVERAGE(Raw_Data!T:T) -> 1120.2312
A12: Supplier Savings by Industry
A13: Packaging | B13: =SUMIFS(Raw_Data!T:T,Raw_Data!D:D,A13) -> 316375.05
A14: Ingredients | B14: =SUMIFS(Raw_Data!T:T,Raw_Data!D:D,A14) -> 459072.98
A15: Components | B15: =SUMIFS(Raw_Data!T:T,Raw_Data!D:D,A15) -> 299044.88
A16: Logistics | B16: =SUMIFS(Raw_Data!T:T,Raw_Data!D:D,A16) -> 373499.71
A17: MRO | B17: =SUMIFS(Raw_Data!T:T,Raw_Data!D:D,A17) -> 232354.17
A20: Supplier Savings by Region
A21: US | B21: =SUMIFS(Raw_Data!T:T,Raw_Data!C:C,A21) -> 330473.53
A22: Canada | B22: =SUMIFS(Raw_Data!T:T,Raw_Data!C:C,A22) -> 314319.54
A23: Mexico | B23: =SUMIFS(Raw_Data!T:T,Raw_Data!C:C,A23) -> 330318.64
A24: Europe | B24: =SUMIFS(Raw_Data!T:T,Raw_Data!C:C,A24) -> 390753.56
A25: APAC | B25: =SUMIFS(Raw_Data!T:T,Raw_Data!C:C,A25) -> 314481.54
A28: Supplier Savings by Supplier Size
A29: Small | B29: =SUMIFS(Raw_Data!T:T,Raw_Data!E:E,A29) -> 701926.96
A30: Medium | B30: =SUMIFS(Raw_Data!T:T,Raw_Data!E:E,A30) -> 698307.29
A31: Large | B31: =SUMIFS(Raw_Data!T:T,Raw_Data!E:E,A31) -> 280112.55
A35: Top SCF Opportunity Suppliers
A36: Supplier Name | B36: Region | C36: Industry | D36: Opportunity Score
A37: RedRock Supply | B37: =_xlfn.XLOOKUP(A37,Raw_Data!B:B,Raw_Data!C:C) -> Europe | C37: =_xlfn.XLOOKUP(A37,Raw_Data!B:B,Raw_Data!D:D) -> MRO | D37: 113236.75
A38: Titan Partners | B38: =_xlfn.XLOOKUP(A38,Raw_Data!B:B,Raw_Data!C:C) -> US | C38: =_xlfn.XLOOKUP(A38,Raw_Data!B:B,Raw_Data!D:D) -> Logistics | D38: 110222.06
A39: Titan Supply | B39: =_xlfn.XLOOKUP(A39,Raw_Data!B:B,Raw_Data!C:C) -> Europe | C39: =_xlfn.XLOOKUP(A39,Raw_Data!B:B,Raw_Data!D:D) -> Packaging | D39: 96743.936
A40: SilverLine Group | B40: =_xlfn.XLOOKUP(A40,Raw_Data!B:B,Raw_Data!C:C) -> APAC | C40: =_xlfn.XLOOKUP(A40,Raw_Data!B:B,Raw_Data!D:D) -> Ingredients | D40: 94542.15
A41: RedRock Solutions | B41: =_xlfn.XLOOKUP(A41,Raw_Data!B:B,Raw_Data!C:C) -> Mexico | C41: =_xlfn.XLOOKUP(A41,Raw_Data!B:B,Raw_Data!D:D) -> Packaging | D41: 76858.183
A42: RedRock Logistics | B42: =_xlfn.XLOOKUP(A42,Raw_Data!B:B,Raw_Data!C:C) -> Canada | C42: =_xlfn.XLOOKUP(A42,Raw_Data!B:B,Raw_Data!D:D) -> Packaging | D42: 62917.975
A43: SilverLine Supply | B43: =_xlfn.XLOOKUP(A43,Raw_Data!B:B,Raw_Data!C:C) -> US | C43: =_xlfn.XLOOKUP(A43,Raw_Data!B:B,Raw_Data!D:D) -> Logistics | D43: 55904.582
A44: Delta Logistics | B44: =_xlfn.XLOOKUP(A44,Raw_Data!B:B,Raw_Data!C:C) -> Europe | C44: =_xlfn.XLOOKUP(A44,Raw_Data!B:B,Raw_Data!D:D) -> Ingredients | D44: 53927.99
A45: SwiftHaul Components | B45: =_xlfn.XLOOKUP(A45,Raw_Data!B:B,Raw_Data!C:C) -> Europe | C45: =_xlfn.XLOOKUP(A45,Raw_Data!B:B,Raw_Data!D:D) -> Packaging | D45: 53896.69
A46: Nova Supply | B46: =_xlfn.XLOOKUP(A46,Raw_Data!B:B,Raw_Data!C:C) -> APAC | C46: =_xlfn.XLOOKUP(A46,Raw_Data!B:B,Raw_Data!D:D) -> Components | D46: 52902.96
A50: SCF Program Revenue Potential
A52: Potential Financing Volume | B52: =SUMPRODUCT(Raw_Data!H2:H1501,Raw_Data!Q2:Q1501) -> 43942944
A53: Average SCF Margin | B53: =B5-B6 -> 0.0662786
A54: Estimated Annual SCF Revenue | B54: =B52*B53 -> 2912476.8
...

Sheet Lookup_Lists
A1: Region | B1: Industry | C1: Supplier_Size | D1: Payment_Terms_Days | E1: Critical_Supplier_Flag | F1: Program_Eligible
A2: US | B2: Packaging | C2: Small | D2: 30 | E2: Yes | F2: Yes
A3: Canada | B3: Ingredients | C3: Medium | D3: 45 | E3: No | F3: No
A4: Mexico | B4: Components | C4: Large | D4: 60
A5: Europe | B5: Logistics | D5: 90
A6: APAC | B6: MRO

Sheet README
